<mujoco model="GH2">
    <!-- <compiler discardvisual="false" /> -->
    <!-- angle="radian" -->
    <!-- <option timestep="0.005" iterations="50" solver="Newton" tolerance="1e-10"/> -->

    <!-- <size njmax="50" nconmax="10" nstack="200"/> -->

    <asset>
        <mesh name="shoulder0_mesh" file="meshes/mm/shoulder_0.stl" scale="0.001 0.001 0.001"/>
        <mesh name="shoulder1_mesh" file="meshes/mm/shoulder_1.stl" scale="0.001 0.001 0.001"/>
        <mesh name="shoulder2_mesh" file="meshes/mm/shoulder_2.stl" scale="0.001 0.001 0.001"/>
        <mesh name="shoulder3_mesh" file="meshes/mm/shoulder_3.stl" scale="0.001 0.001 0.001"/>
        <mesh name="upper_arm0_mesh" file="meshes/mm/upper_arm_0.stl" scale="0.001 0.001 0.001"/>
        <mesh name="upper_arm1_mesh" file="meshes/mm/upper_arm_1.stl" scale="0.001 0.001 0.001"/>
        <mesh name="upper_arm2_mesh" file="meshes/mm/upper_arm_2.stl" scale="0.001 0.001 0.001"/>
        <mesh name="lower_arm0_mesh" file="meshes/mm/lower_arm_0.stl" scale="0.001 0.001 0.001"/>
        <mesh name="lower_arm1_mesh" file="meshes/mm/lower_arm_1.stl" scale="0.001 0.001 0.001"/>
        <mesh name="lower_arm2_mesh" file="meshes/mm/lower_arm_2.stl" scale="0.001 0.001 0.001"/>

        <mesh name="shoulder_pulley" file="meshes/mm/shoulder_pulley_asy.stl" scale="0.001 0.001 0.001"/>
        <mesh name="arm_pulley" file="meshes/mm/upper_arm_0_pulley.stl" scale="0.001 0.001 0.001"/>
    </asset> 

    <default>
        <!-- <geom rgba=".9 .7 .1 1" size="0.01"/> -->
        <site type="sphere" rgba=".9 .9 .9 1" size="5E-03"/>
        <joint damping="0.1"/>
        <!-- <joint type="hinge" axis="0 1 0" limited="true" range="0 60" solimplimit="0.95 0.95 0.1"/> -->
        <muscle ctrllimited="true" ctrlrange="0 1"/>
    </default>

    <worldbody>
        <body name="base" pos="0 0 0">
            <!-- robot view -->
            <camera mode="fixed" name="robotview" pos="1.0 0 0.4" quat="0.653 0.271 0.271 0.653"/>
            <inertial diaginertia="0 0 0" mass="0" pos="0 0 0"/>
            <!-- mount attached here -->

            <!-- <body name="shoulder0" pos="860E-03 -300E-03 800E-03" euler="1.571 0 0"> -->
            <body name="shoulder0" pos="-0.1 0 0.5" euler="1.571 1.571 0">
                <geom name="shoulder0_vis" group="1" type="mesh" contype="0" conaffinity="0" mesh="shoulder0_mesh" pos="0 0 0" euler="0 0 0"/>
                <geom name="shoulder0_col_back" group="0" type="box" pos="0 -140.5E-03 25E-03" size="86E-03 140.5E-03 31E-03" rgba=".95 .1 .1 0.6"/>
                <geom name="shoulder0_col_top_1" group="0" type="box" pos="0 -6E-03 85E-03" size="86E-03 6E-03 91E-03" rgba=".95 .1 .1 0.0"/>
                <geom name="shoulder0_col_top_2" group="0" type="cylinder" fromto="0 0 176E-03 0 -12E-03 176E-03" size="86E-03" rgba=".95 .1 .1 0.6"/>
                <geom name="shoulder0_col_bot_1" group="0" type="box" pos="0 -275E-03 85E-03" size="86E-03 6E-03 91E-03" rgba=".95 .1 .1 0.6"/>
                <geom name="shoulder0_col_bot_2" group="0" type="cylinder" fromto="0 -269E-03 176E-03 0 -281E-03 176E-03" size="86E-03" rgba=".95 .1 .1 0.6"/>

                <!-- <inertial pos="0 0 0" mass="8.82" fullinertia="0.118 0.133 0.0716 0.0 0.00511 0.0"/> -->
                <site name="shoulder1_right_side" pos="100E-03 -21E-03 176E-03" />
                <site name="shoulder1_left_side" pos="-100E-03 -21E-03 176E-03" />
            
                <body name="shoulder0_pulley_right" pos="65.824E-03 -12.80E-03 47.292E-03" euler="-1.571 0 0">
                    <!-- <joint name="shoulder0_pulley_right_joint" type="hinge" axis="0 0 1" pos="0 0 0" limited="true" range="-90 90" damping="0.1"/> -->
                    <geom name="shoulder0_pulley_right_vis" group="1" contype="0" conaffinity="0" type="mesh" mesh="shoulder_pulley" pos="0 0 0" euler="0 0 0"/>
                    <geom name="shoulder0_pulley_right_col" group="4" type="cylinder" fromto="0 0 0 0 0 -18E-03" size="19E-03" rgba=".2 .2 .5 0.6" />
                    <geom name="shoulder0_pulley_right_col_outer" group="0" type="cylinder" fromto="0 0 0 0 0 -20E-03" size="33.5E-03" rgba=".95 .1 .1 0.6" />

                    <inertial pos="0.176E-03 -0.091E-03 -10.188E-03" mass="30.516E-03" diaginertia="0 0 0"/>
                    <!-- <site name="shoulder0_pulley_right_top_site" pos="22E-03 0E-03 -6.85E-03" />
                    <site name="shoulder0_pulley_right_bot_site" pos="-22E-03 0E-03 -15.35E-03" /> -->
                    <site name="shoulder0_pulley_right_top_site" pos="17.9548E-03 -1.2751E-03 -6.85E-03" />
                    <site name="shoulder0_pulley_right_bot_site" pos="-11.5297E-03 13.8227E-03 -15.35E-03" />
                    <!-- <site name="side_right" pos="22E-03 22E-03 -14.85E-03" /> -->
                </body>

                <body name="shoulder0_pulley_left" pos="-65.9E-03 -16.105E-03 47.324E-03" euler="-1.571 0 0">
                    <!-- <joint name="shoulder0_pulley_left_joint" axis="0 0 1" pos="0 0 0" limited="true" range="-90 90" damping="0.1"/> -->
                    <geom name="shoulder0_pulley_left_vis" group="1" contype="0" conaffinity="0" type="mesh" mesh="shoulder_pulley" pos="0 0 0" euler="0 0 0"/>
                    <geom name="shoulder0_pulley_left_col" group="4" type="cylinder" fromto="0 0 0 0 0 -18E-03" size="19E-03" rgba=".2 .2 .5 0.6" />
                    <geom name="shoulder0_pulley_left_col_outer" group="0" type="cylinder" fromto="0 0 0 0 0 -20E-03" size="33.5E-03" rgba=".95 .1 .1 0.6" />

                    <inertial pos="0.176E-03 -0.091E-03 -10.188E-03" mass="30.516E-03" diaginertia="0 0 0"/>
                    <!-- <site name="shoulder0_pulley_left_top_site" pos="-22E-03 0E-03 -6.85E-03" />
                    <site name="shoulder0_pulley_left_bot_site" pos="22E-03 0E-03 -15.35E-03" /> -->
                    <site name="shoulder0_pulley_left_top_site" pos="-17.9556E-03 -1.2634E-03 -15.35E-03" />
                    <site name="shoulder0_pulley_left_bot_site" pos="11.5330E-03 13.8199E-03 -6.85E-03" />
                    <!-- <site name="side_left" pos="-22E-03 22E-03 -14.85E-03" /> -->
                </body>

                <body name="shoulder1" pos="0E-03 169E-03 -6E-03">
                    <joint name="shoulder1_joint" type="hinge" axis="0 1 0" pos="0E-03 -200E-03 183E-03" limited="true" range="-1.571 1.571" />
                    <geom name="shoulder1_vis" group="1" type="mesh" mesh="shoulder1_mesh" contype="0" conaffinity="0" pos="0 0 0" euler="0 0 0"/>
                    <geom name="shoulder1_col" group="4" type="cylinder" fromto="0E-03 -184.8E-03 182E-03 0 -200.8E-03 182E-03" size="75E-03" rgba=".2 .2 .5 0.6" />
                    <geom name="shoulder1_col_outer" group="0" type="cylinder" fromto="0E-03 -184.8E-03 182E-03 0 -434.2E-03 182E-03" size="81E-03" rgba=".95 .1 .1 0.6" />

                    <!-- <inertial pos="0.001215 0.000372 -0.0358" mass="1.473" diaginertia="0.0171 0.0181 0.00666"/> -->
                    <inertial pos="-0.205E-03 -331.772E-03 183.388E-03" mass="1502.577E-03" fullinertia="18398308.205E-09 6467418.827E-09 17206193.595E-09 -29241.955E-09 72684.44E-09 188210.917E-09" /> 
                    <site name="shoulder1_attachment_top_right" pos="45.636E-03 -189.068E-03 243.357E-03"/>
                    <site name="shoulder1_attachment_top_left" pos="23.396E-03 -189.068E-03 254.855E-03"/>
                    <site name="shoulder1_attachment_bot_right" pos="-23.396E-03 -196.532E-03 254.855E-03"/>
                    <site name="shoulder1_attachment_bot_left" pos="-45.636E-03 -196.532E-03 243.357E-03"/>
                    <site name="shoulder2_siteside_right" pos="53E-03 -289.8E-03 221.175E-03" />
                    <site name="shoulder2_siteside_left" pos="-53E-03 -289.8E-03 230.425E-03" />

                    <body name="shoulder1_pulley_right" pos="63.623E-03 -394.244E-03 230.139E-03">
                        <!-- <joint name="shoulder1_pulley_right_joint" type="hinge" axis="0 0 1" pos="0 0 0" limited="true" range="-90 90" damping="0.1"/> -->
                        <geom name="shoulder1_pulley_right_vis" group="1" type="mesh" mesh="shoulder_pulley" contype="0" conaffinity="0" pos="0 0 0" euler="0 0 0"/>
                        <geom name="shoulder1_pulley_right_col" group="4" type="cylinder" fromto="0 0 0 0 0 -18E-03" size="19E-03" rgba=".2 .2 .5 0.6" />
                        <geom name="shoulder1_pulley_right_col_outer" group="0" type="cylinder" fromto="0 0 0 0 0 -20E-03" size="33.5E-03" rgba=".95 .1 .1 0.6" />

                        <inertial pos="0.176E-03 -0.091E-03 -10.188E-03" mass="30.516E-03" diaginertia="0 0 0"/>
                        <site name="shoulder1_pulley_right_back_site" pos="22E-03 0E-03 -14.85E-03" />
                        <site name="shoulder1_pulley_right_front_site" pos="-22E-03 0E-03 -6.85E-03" />
                    </body>

                    <body name="shoulder1_pulley_left" pos="-63.7E-03 -394.276E-03 239.461E-03">
                        <!-- <joint name="shoulder1_pulley_left_joint" type="hinge" axis="0 0 1" pos="0 0 0" limited="true" range="-90 90" damping="0.1"/> -->
                        <geom name="shoulder1_pulley_left_vis" group="1" type="mesh" mesh="shoulder_pulley" contype="0" conaffinity="0" pos="0 0 0" euler="0 0 0"/>
                        <geom name="shoulder1_pulley_left_col" group="4" type="cylinder" fromto="0 0 0 0 0 -18E-03" size="19E-03" rgba=".2 .2 .5 0.6" />
                        <geom name="shoulder1_pulley_left_col_outer" group="0" type="cylinder" fromto="0 0 0 0 0 -20E-03" size="33.5E-03" rgba=".95 .1 .1 0.6" />

                        <inertial pos="0.176E-03 -0.091E-03 -10.188E-03" mass="30.516E-03" diaginertia="0 0 0"/>
                        <site name="shoulder1_pulley_left_back_site" pos="-22E-03 0E-03 -14.85E-03" />
                        <site name="shoulder1_pulley_left_front_site" pos="22E-03 0E-03 -6.85E-03" />
                    </body>
                    
                    <body name="shoulder2" pos="0 -450E-03 -550E-03">
                        <joint name="shoulder2_joint" type="hinge" axis="0 0 1" pos="0 160.2E-03 759.3E-03" limited="true" range="-1.571 1.571" />
                        <geom name="shoulder2_vis" group="1" type="mesh" mesh="shoulder2_mesh" pos="0 0 0" euler="0 0 0"/>
                        <geom name="shoulder2_col" group="4" type="cylinder" fromto="0 160.2E-03 766.675E-03 0 160.2E-03 784.955E-03" size="51E-03" rgba=".2 .2 .5 0.6" />
                        <geom name="shoulder2_col_outer" group="0" type="cylinder" fromto="0 160.2E-03 645E-03 0 160.2E-03 819E-03" size="75E-03" rgba=".95 .1 .1 0.6" />
                        <inertial pos="0.349E-03 166.878E-03 767.957E-03" mass="1201.742E-03" fullinertia="7400186.602E-09 7926648.631E-09 2885409.437E-09 -22702.31E-09 -55325.609E-09 -1258840.778E-09"/>
                        <geom name="shoulder23_col" type="cylinder" fromto="-12.3E-03 182.7E-03 808.1E-03 12.3E-03 182.7E-03 808.1E-03" size="9.5E-03" rgba=".2 .2 .5 0.6" />
                        
                        <!-- <site name="shoulder2_site" pos="0 211.2 770"/> -->
                        <site name="shoulder2_attachment_back_right" pos="-15.523E-03 212.964E-03 771.175E-03"/>
                        <site name="shoulder2_attachment_back_left" pos="-28.01E-03 207.533E-03 771.175E-03"/>
                        <site name="shoulder2_attachment_front_right" pos="29.232E-03 206.788E-03 780.425E-03"/>
                        <site name="shoulder2_attachment_front_left" pos="16.891E-03 212.542E-03 780.425E-03"/>
                        <site name="shoulder23_bot_side" pos="0E-03 170E-03 808.1E-03" />
                        <site name="shoulder23_front_right_site" pos="6.5E-03 182.7E-03 820E-03" />
                        <site name="shoulder23_front_left_site" pos="-6.5E-03 182.7E-03 820E-03" />
                        <site name="shoulder3_top_side" pos="0E-03 272.096E-03 902.801E-03"/>
                        <site name="shoulder3_bot_side" pos="0E-03 165.096E-03 902.801E-03"/>

                        <body name="shoulder2_pulley_right" pos="3.102E-03 160.822E-03 713.8E-03" euler="0 -1.571 0">
                            <!-- <joint name="shoulder2_pulley_right_joint" type="hinge" axis="0 0 1" pos="0 0 0" limited="true" range="-90 90" damping="0.1"/> -->
                            <geom name="shoulder2_pulley_right_vis" group="1" type="mesh" mesh="shoulder_pulley" contype="0" conaffinity="0" pos="0 0 0" euler="0 0 0"/>
                            <geom name="shoulder2_pulley_right_col" type="cylinder" fromto="0 0 0 0 0 -18E-03" size="19E-03" rgba=".2 .2 .5 0.6" />
                            <inertial pos="0.176E-03 -0.091E-03 -10.188E-03" mass="30.516E-03" diaginertia="0 0 0"/>
                            <site name="shoulder2_pulley_right_top_site" pos="0 22E-03 -10E-03" />
                            <site name="shoulder2_pulley_right_bot_site" pos="0 -22E-03 -10E-03" />
                        </body>

                        <body name="shoulder2_pulley_left" pos="-3.102E-03 160.822E-03 713.8E-03" euler="0 1.571 0">
                            <!-- <joint name="shoulder2_pulley_left_joint" type="hinge" axis="0 0 1" pos="0 0 0" limited="true" range="-90 90" damping="0.1"/> -->
                            <geom name="shoulder2_pulley_left_vis" group="1" type="mesh" mesh="shoulder_pulley" contype="0" conaffinity="0" pos="0 0 0" euler="0 0 0"/>
                            <geom name="shoulder2_pulley_left_col" type="cylinder" fromto="0 0 0 0 0 -18E-03" size="19E-03" rgba=".2 .2 .5 0.6" />
                            <inertial pos="0.176E-03 -0.091E-03 -10.188E-03" mass="30.516E-03" diaginertia="0 0 0"/>
                            <site name="shoulder2_pulley_left_top_site" pos="0 22E-03 -10E-03" />
                            <site name="shoulder2_pulley_left_bot_site" pos="0 -22E-03 -10E-03" />
                        </body>

                        <body name="shoulder3" pos="0 220.096E-03 902.801E-03" euler="0 0 0">
                            <joint name="shoulder3_joint" type="hinge" axis="1 0 0" pos="0 0 0" limited="true" range="-1.571 0" />
                            <geom name="shoulder3_vis" group="1" type="mesh" mesh="shoulder3_mesh" pos="0 0 0" euler="0 0 0"/>
                            <geom name="shoulder3_col" type="cylinder" fromto="-11E-03 0 0 11E-03 0 0" size="51E-03" rgba=".2 .2 .5 0.6" />
                            <inertial pos="-0.095E-03 -11.837E-03 9.267E-03" mass="424.969E-03" fullinertia="454444.682E-09 682518.716E-09 704831.844E-09 -2387.856E-09 1975.761E-09 68092.245E-09"/>

                            <site name="shoulder3_attachment_top_right" pos="5.501E-03 0 52E-03"/>
                            <site name="shoulder3_attachment_top_left" pos="-5.501E-03 0 52E-03"/>
                            <site name="shoulder3_attachment_bot_right" pos="5.499E-03 -51.921E-03 2.816E-03" />
                            <site name="shoulder3_attachment_bot_left" pos="-5.499E-03 -51.921E-03 2.816E-03" />
                            

                            <body name="upper_arm0" pos="129.413E-03 -103.681E-03 41.961E-03" euler="0 -1.571 1.571">
                                <geom name="upper_arm0_vis" group="1" type="mesh" mesh="upper_arm0_mesh" pos="0 0 0" euler="0 0 0"/>
                                <inertial pos="17.66E-03 24.576E-03 131.938E-03" mass="633.245E-03" fullinertia="2268038.331E-09 2311543.439E-09 743639.018E-09 140303.655E-09 126521.58E-09 14062.187E-09"/>

                                <site name="upper_arm1_bot_side" pos="-34.515E-03 111.585E-03 119.413E-03" />
                                <site name="upper_arm1_mid_bot_side" pos="-26.515E-03 10.585E-03 129.413E-03" />
                                <site name="upper_arm1_mid_top_side" pos="-19.515E-03 30.085E-03 170.413E-03" />
                                <site name="upper_arm1_top_side" pos="-10.515E-03 111.585E-03 119.413E-03" />
                                
                                <body name="upper_arm0_pulley_right" pos="-1.599E-03 19.145E-03 59.413E-03" euler="0 3.142 0">
                                    <!-- <joint name="upper_arm0_pulley_right_joint" type="hinge" axis="1 0 0" pos="0 0 0" limited="true" range="-90 90" damping="0.1"/> -->
                                    <geom name="upper_arm0_pulley_right_vis" group="1" type="mesh" mesh="arm_pulley" contype="0" conaffinity="0" pos="0 0 0" euler="0 0 0"/>
                                    <geom name="upper_arm0_pulley_right_col" type="cylinder" fromto="0 0 0 19.5E-03 0 0" size="16E-03" rgba=".2 .2 .5 0.6" />
                                    <inertial pos="11.312E-03 -0.056E-03 0.025E-03" mass="17.631E-03" diaginertia="0 0 0"/>
                                    <site name="upper_arm0_pulley_right_top_site" pos="9E-03 18E-03 0" />
                                    <site name="upper_arm0_pulley_right_bot_site" pos="15E-03 -18E-03 0" />
                                </body>

                                <body name="upper_arm0_pulley_left" pos="-18.599E-03 19.395E-03 199.413E-03" euler="0 3.142 0">
                                    <!-- <joint name="upper_arm0_pulley_left_joint" type="hinge" axis="1 0 0" pos="0 0 0" limited="true" range="-90 90" damping="0.1"/> -->
                                    <geom name="upper_arm0_pulley_left_vis" group="1" type="mesh" mesh="arm_pulley" contype="0" conaffinity="0" pos="0 0 0" euler="0 0 0"/>
                                    <geom name="upper_arm0_pulley_left_col" type="cylinder" fromto="0 0 0 19.5E-03 0 0" size="16E-03" rgba=".2 .2 .5 0.6" />
                                    <inertial pos="11.312E-03 -0.056E-03 0.025E-03" mass="17.631E-03" diaginertia="0 0 0"/>
                                    <site name="upper_arm0_pulley_left_top_site" pos="9E-03 -18E-03 0" />
                                    <site name="upper_arm0_pulley_left_bot_site" pos="15E-03 18E-03 0" />
                                </body>

                                <body name="upper_arm1" pos="-266.415E-03 -110.238E-03 129.413E-03" euler="1.571 0 -1.571">
                                    <joint name="upper_arm1_joint" type="hinge" axis="0 1 0" pos="0.338E-03 284.517E-03 -166.883E-03" limited="true" range="-0.6 3.2" />
                                    <geom name="upper_arm1_vis" group="1" type="mesh" mesh="upper_arm1_mesh" pos="0 0 0" euler="0 0 0"/>
                                    <geom name="upper_arm1_col" type="cylinder" fromto="0.112E-03 226.899E-03 -166.823E-03 0.112E-03 260.899E-03 -166.823E-03" size="43.5E-03" rgba=".2 .2 .5 0.6" />
                                    <inertial pos="0.776E-03 186.948E-03 -164.642E-03" mass="561.157E-03" fullinertia="1419828.174E-09 595869.545E-09 1329433.042E-09 34079.138E-09 -62470.548E-09 110862.233E-09"/>
                                    
                                    <site name="upper_arm1_attachment_bot" pos="2.089E-03 231.9E-03 -120.879E-03" />
                                    <site name="upper_arm1_attachment_mid_bot" pos="2.089E-03 239.9E-03 -120.879E-03" />
                                    <site name="upper_arm1_attachment_mid_top" pos="37.49E-03 248.175E-03 -192.08E-03" />
                                    <site name="upper_arm1_attachment_top" pos="37.49E-03 256.161E-03 -192.08E-03" />
                                    <site name="upper_arm2_right_front_side" pos="54.796E-03 92.702E-03 -92.137E-03" />
                                    <site name="upper_arm2_right_back_side" pos="33.796E-03 92.702E-03 -179.137E-03" />
                                    <site name="upper_arm2_left_front_side" pos="-14.39E-03 92.702E-03 -78.436E-03" />
                                    <site name="upper_arm2_left_back_side" pos="-35.39E-03 92.702E-03 -163.436E-03" />

                                    <body name="upper_arm1_pulley_right" pos="31.610E-03 187.649E-03 -147.921E-03" euler="0 0.244346 0">
                                        <!-- <joint name="upper_arm1_pulley_right_joint" type="hinge" axis="1 0 0" pos="0 0 0" limited="true" range="-90 90" damping="0.1"/> -->
                                        <geom name="upper_arm1_pulley_right_vis" group="1" type="mesh" mesh="arm_pulley" contype="0" conaffinity="0" pos="0 0 0" euler="0 0 0"/>
                                        <geom name="upper_arm1_pulley_right_col" type="cylinder" fromto="0 0 0 19.5E-03 0 0" size="16E-03" rgba=".2 .2 .5 0.6" />
                                        <inertial pos="11.312E-03 -0.056E-03 0.025E-03" mass="17.631E-03" diaginertia="0 0 0"/>
                                        <site name="upper_arm1_pulley_right_front_site" pos="15E-03 0 18E-03" />
                                        <site name="upper_arm1_pulley_right_back_site" pos="9E-03 0 -18E-03" />
                                    </body>

                                    <body name="upper_arm1_pulley_left" pos="-31.337E-03 187.399E-03 -185.531E-03" euler="0 3.38594 0">
                                        <!-- <joint name="upper_arm1_pulley_left_joint" type="hinge" axis="1 0 0" pos="0 0 0" limited="true" range="-90 90" damping="0.1"/> -->
                                        <geom name="upper_arm1_pulley_left_vis" group="1" type="mesh" mesh="arm_pulley" contype="0" conaffinity="0" pos="0 0 0" euler="0 0 0"/>
                                        <geom name="upper_arm1_pulley_left_col" type="cylinder" fromto="0 0 0 19.5E-03 0 0" size="16E-03" rgba=".2 .2 .5 0.6" />
                                        <inertial pos="11.312E-03 -0.056E-03 0.025E-03" mass="17.631E-03" diaginertia="0 0 0"/>
                                        <site name="upper_arm1_pulley_left_front_site" pos="9E-03 0 -18E-03" />
                                        <site name="upper_arm1_pulley_left_back_site" pos="15E-03 0 18E-03" />
                                    </body>

                                    <body name="upper_arm2" pos="0 -75E-03 -305E-03" euler="0 3.38594 0">
                                        <joint name="upper_arm2_joint" type="hinge" axis="-1 0 0" pos="74.211E-03 167.702E-03 -173.794E-03" limited="true" range="-1.5708 1.0" />
                                        <geom name="upper_arm2_vis" group="1" type="mesh" mesh="upper_arm2_mesh" pos="0 0 0" euler="0 -0.244346 0"/>
                                        <geom name="upper_arm2_right_col" type="cylinder" fromto="3.711E-03 167.702E-03 -173.824E-03 -7.539E-03 167.702E-03 -173.828E-03" size="40E-03" rgba=".2 .2 .5 0.6" />
                                        <geom name="upper_arm2_left_col" type="cylinder" fromto="62.961E-03 167.702E-03 -173.799E-03 74.211E-03 167.702E-03 -173.794E-03" size="40E-03" rgba=".2 .2 .5 0.6" />
                                        <inertial pos="33.317119473864E-03 151.976E-03 -175.996713864107E-03" mass="142.481E-03" fullinertia="145650.343E-09 171280.119E-09 219306.753E-09 1211.903E-09 19747.386E-09 5581.458E-09"/>

                                        <site name="upper_arm2_attachment_right" pos="-2.961E-03 151.894E-03 -210.985E-03" />
                                        <site name="upper_arm2_attachment_left" pos="69.797E-03 143.997E-03 -206.863E-03" />

                                        <body name="lower_arm0" pos="32.155E-03 -55.326E-03 -13.959E-03" euler="3.142 1.81514 0">
                                            <geom name="lower_arm0_vis" group="1" type="mesh" mesh="lower_arm0_mesh" pos="0 0 0" euler="0 0 0"/>
                                            <inertial pos="-153.662E-03 -132.192E-03 -37.169E-03" mass="185.569E-03" fullinertia="117040.473E-09 176597.139E-09 178005.055E-09 -12046.39E-09 -16532.198E-09 -2546.136E-09"/>

                                            <body name="lower_arm1" pos="80E-03 0 -180E-03" euler="0 0 0">
                                                <joint name="lower_arm1_joint" type="hinge" axis="0 -1 0" pos="-195.378E-03 -157.128E-03 152.343E-03" limited="true" range="-1.5708 1.5708" />
                                                <geom name="lower_arm1_vis" group="1" type="mesh" mesh="lower_arm1_mesh" pos="0 0 0" euler="0 0 0"/>
                                                <inertial pos="-191.523E-03 -60.805E-03 153.121E-03" mass="419.135E-03" fullinertia="842611.395E-09 420653.406E-09 1001289.454E-09 108289.318E-09 -69795.558E-09 32022.738E-09" />
                                                
                                                <site name="lower_arm2_right_front_side" pos="-220.41E-03 20.456E-03 112.542E-03" />
                                                <site name="lower_arm2_right_back_side" pos="-155.41E-03 20.456E-03 128.542E-03" />
                                                <site name="lower_arm2_left_front_side" pos="-235.227E-03 20.456E-03 175.204E-03" />
                                                <site name="lower_arm2_left_back_side" pos="-170.417E-03 20.456E-03 192.204E-03" />

                                                <body name="lower_arm1_pulley_right" pos="-215.250E-03 -75.045E-03 125.415E-03" euler="0 1.32645 0">
                                                    <!-- <joint name="lower_arm1_pulley_right_joint" type="hinge" axis="1 0 0" pos="0 0 0" limited="true" range="-90 90" damping="0.1"/> -->
                                                    <geom name="lower_arm1_pulley_right_vis" group="1" type="mesh" mesh="arm_pulley" contype="0" conaffinity="0" pos="0 0 0" euler="0 0 0"/>
                                                    <geom name="lower_arm1_pulley_right_col" type="cylinder" fromto="0 0 0 19.5E-03 0 0" size="16E-03" rgba=".2 .2 .5 0.6" />
                                                    <inertial pos="11.312E-03 -0.056E-03 0.025E-03" mass="17.631E-03" diaginertia="0 0 0"/>
                                                    <site name="lower_arm1_pulley_right_front_site" pos="9E-03 0 -18E-03" />
                                                    <site name="lower_arm1_pulley_right_back_site" pos="15E-03 0 18E-03" />
                                                </body>

                                                <body name="lower_arm1_pulley_left" pos="-175.328E-03 -75.045E-03 179.247E-03" euler="0 -1.81514 0">
                                                    <!-- <joint name="lower_arm1_pulley_left_joint" type="hinge" axis="1 0 0" pos="0 0 0" limited="true" range="-90 90" damping="0.1"/> -->
                                                    <geom name="lower_arm1_pulley_left_vis" group="1" type="mesh" mesh="arm_pulley" contype="0" conaffinity="0" pos="0 0 0" euler="0 0 0"/>
                                                    <geom name="lower_arm1_pulley_left_col" type="cylinder" fromto="0 0 0 19.5E-03 0 0" size="16E-03" rgba=".2 .2 .5 0.6" />
                                                    <inertial pos="11.312E-03 -0.056E-03 0.025E-03" mass="17.631E-03" diaginertia="0 0 0"/>
                                                    <site name="lower_arm1_pulley_left_front_site" pos="15E-03 0 18E-03" />
                                                    <site name="lower_arm1_pulley_left_back_site" pos="9E-03 0 -18E-03" />
                                                </body>

                                                <body name="lower_arm2" pos="-148.258E-03 209.549E-03 188.662E-03" euler="0 -1.81514 3.14159">
                                                    <joint name="lower_arm2_joint" type="hinge" axis="1 0 0" pos="62.248E-03 189.093E-03 54.475E-03" limited="true" range="-1.5708 1.5708" />
                                                    <geom name="lower_arm2_vis" group="1" type="mesh" mesh="lower_arm2_mesh" pos="0 0 0" euler="0 0 0"/>
                                                    <geom name="lower_arm2_right_col" type="cylinder" fromto="50.999E-03 189.093E-03 54.47E-03 62.248E-03 189.093E-03 54.48E-03" size="30E-03" rgba=".2 .2 .5 0.6" />
                                                    <geom name="lower_arm2_left_col" type="cylinder" fromto="-14.501E-03 189.093E-03 54.437E-03 -3.251E-03 189.093E-03 54.443E-03" size="30E-03" rgba=".2 .2 .5 0.6" />
                                                    <inertial pos="23.958E-03 180.342E-03 54.226E-03" mass="110.187E-03" fullinertia="68200.199E-09 110041.672E-09 132740.814E-09 -14.833E-09 -2.93E-09 -1049.623E-09"/>

                                                    <site name="lower_arm2_attachment_right" pos="57.1E-03 157.167E-03 56.66E-03" />
                                                    <site name="lower_arm2_attachment_left" pos="-9.378E-03 157.167E-03 56.542E-03" />

                                                    <site name="testing" pos="23.874E-03 143.393E-03 53.956E-03" />
                                                    <body name="right_hand" pos="23.874E-03 143.393E-03 53.956E-03" euler="1.5708 0 0">
                                                        <!-- This camera points out from the eef. -->
                                                        <camera mode="fixed" name="eye_in_hand" pos="0.05 0 0" quat="0 0.707108 0.707108 0" fovy="75"/>
                                                        <!-- to add gripper -->
                                                    </body>
                                                </body>
                                            </body>
                                        </body>
                                    </body>
                                </body>
                            </body>
                        </body>
                    </body>
                </body>
            </body>
        </body>
    </worldbody>

    <tendon>
        <spatial name="shoulder0_tendon_right_top" width="2E-03" rgba=".95 .3 .3 1" >
            <site site="shoulder0_pulley_right_top_site" />
            <geom geom="shoulder1_col" sidesite="shoulder1_right_side" />
            <site site="shoulder1_attachment_top_right" />         
        </spatial>

        <spatial name="shoulder0_tendon_right_bot" width="2E-03" rgba=".95 .3 .3 1" >
            <site site="shoulder0_pulley_right_bot_site" />
            <geom geom="shoulder1_col" sidesite="shoulder1_left_side" />
            <site site="shoulder1_attachment_top_left" />         
        </spatial>

        <spatial name="shoulder0_tendon_left_top" width="2E-03" rgba=".3 .95 .3 1" >
            <site site="shoulder0_pulley_left_top_site" />
            <geom geom="shoulder1_col" sidesite="shoulder1_left_side"/>
            <site site="shoulder1_attachment_bot_left" />         
        </spatial>

        <spatial name="shoulder0_tendon_left_bot" width="2E-03" rgba=".3 .95 .3 1" >
            <site site="shoulder0_pulley_left_bot_site" />
            <geom geom="shoulder1_col" sidesite="shoulder1_right_side"/>
            <site site="shoulder1_attachment_bot_right" />         
        </spatial>

        <spatial name="shoulder1_tendon_back_right" width="2E-03" rgba=".95 .3 .3 1" >
            <site site="shoulder1_pulley_right_back_site" />
            <geom geom="shoulder2_col" sidesite="shoulder2_siteside_right" />
            <site site="shoulder2_attachment_back_right" />         
        </spatial>

        <spatial name="shoulder1_tendon_back_left" width="2E-03" rgba=".95 .3 .3 1" >
            <site site="shoulder1_pulley_right_front_site" />
            <geom geom="shoulder2_col" sidesite="shoulder2_siteside_left" />
            <site site="shoulder2_attachment_back_left" />         
        </spatial>

        <spatial name="shoulder1_tendon_front_left" width="2E-03" rgba=".3 .95 .3 1" >
            <site site="shoulder1_pulley_left_back_site" />
            <geom geom="shoulder2_col" sidesite="shoulder2_siteside_left" />
            <site site="shoulder2_attachment_front_left" />         
        </spatial>

        <spatial name="shoulder1_tendon_front_right" width="2E-03" rgba=".3 .95 .3 1" >
            <site site="shoulder1_pulley_left_front_site" />
            <geom geom="shoulder2_col" sidesite="shoulder2_siteside_right" />
            <site site="shoulder2_attachment_front_right" />         
        </spatial>

        <spatial name="shoulder2_tendon_right_top" width="2E-03" rgba=".95 .3 .3 1" >
            <site site="shoulder2_pulley_right_top_site" />
            <geom geom="shoulder23_col" sidesite="shoulder23_bot_side" />
            <site site="shoulder23_front_right_site" /> 
            <geom geom="shoulder3_col" sidesite="shoulder3_top_side" />
            <site site="shoulder3_attachment_top_right" /> 
        </spatial>

        <spatial name="shoulder2_tendon_right_bot" width="2E-03" rgba=".95 .3 .3 1" >
            <site site="shoulder2_pulley_right_bot_site" />
            <geom geom="shoulder3_col" sidesite="shoulder3_bot_side"/>
            <site site="shoulder3_attachment_bot_right" /> 
        </spatial>

        <spatial name="shoulder2_tendon_left_top" width="2E-03" rgba=".3 .95 .3 1" >
            <site site="shoulder2_pulley_left_top_site" />
            <geom geom="shoulder23_col" sidesite="shoulder23_bot_side" />
            <site site="shoulder23_front_left_site" /> 
            <geom geom="shoulder3_col" sidesite="shoulder3_top_side" />
            <site site="shoulder3_attachment_top_left" /> 
        </spatial>

        <spatial name="shoulder2_tendon_left_bot" width="2E-03" rgba=".3 .95 .3 1" >
            <site site="shoulder2_pulley_left_bot_site" />
            <geom geom="shoulder3_col" sidesite="shoulder3_bot_side"/>
            <site site="shoulder3_attachment_bot_left" /> 
        </spatial>

        <spatial name="upper_arm0_tendon_right_top" width="2E-03" rgba=".95 .3 .3 1" >
            <site site="upper_arm0_pulley_right_top_site" />
            <geom geom="upper_arm1_col" sidesite="upper_arm1_top_side"/>
            <site site="upper_arm1_attachment_top" />         
        </spatial>

        <spatial name="upper_arm0_tendon_right_bot" width="2E-03" rgba=".95 .3 .3 1" >
            <site site="upper_arm0_pulley_right_bot_site" />
            <geom geom="upper_arm1_col" sidesite="upper_arm1_mid_top_side" />
            <site site="upper_arm1_attachment_mid_top" />         
        </spatial>

        <spatial name="upper_arm0_tendon_left_top" width="2E-03" rgba=".3 .95 .3 1" >
            <site site="upper_arm0_pulley_left_top_site" />
            <geom geom="upper_arm1_col" sidesite="upper_arm1_mid_bot_side" />
            <site site="upper_arm1_attachment_mid_bot" />         
        </spatial>

        <spatial name="upper_arm0_tendon_left_bot" width="2E-03" rgba=".3 .95 .3 1" >
            <site site="upper_arm0_pulley_left_bot_site" />
            <geom geom="upper_arm1_col" sidesite="upper_arm1_bot_side" />
            <site site="upper_arm1_attachment_bot" />         
        </spatial>

        <spatial name="upper_arm1_tendon_right_front" width="2E-03" rgba=".95 .3 .3 1" >
            <site site="upper_arm1_pulley_right_front_site" />
            <geom geom="upper_arm2_right_col" sidesite="upper_arm2_right_front_side"/>
            <site site="upper_arm2_attachment_right" />         
        </spatial>

        <spatial name="upper_arm1_tendon_right_back" width="2E-03" rgba=".95 .3 .3 1" >
            <site site="upper_arm1_pulley_right_back_site" />
            <geom geom="upper_arm2_right_col" sidesite="upper_arm2_right_back_side"/>
            <site site="upper_arm2_attachment_right" />         
        </spatial>

        <spatial name="upper_arm1_tendon_left_front" width="2E-03" rgba=".3 .95 .3 1" >
            <site site="upper_arm1_pulley_left_front_site" />
            <geom geom="upper_arm2_left_col" sidesite="upper_arm2_left_front_side" />
            <site site="upper_arm2_attachment_left" />         
        </spatial>

        <spatial name="upper_arm1_tendon_left_back" width="2E-03" rgba=".3 .95 .3 1" >
            <site site="upper_arm1_pulley_left_back_site" />
            <geom geom="upper_arm2_left_col" sidesite="upper_arm2_left_back_side" />
            <site site="upper_arm2_attachment_left" />         
        </spatial>
                
        <spatial name="lower_arm1_tendon_right_front" width="2E-03" rgba=".95 .3 .3 1" >
            <site site="lower_arm1_pulley_right_front_site" />
            <geom geom="lower_arm2_right_col" sidesite="lower_arm2_right_front_side"/>
            <site site="lower_arm2_attachment_right" />         
        </spatial>

        <spatial name="lower_arm1_tendon_right_back" width="2E-03" rgba=".95 .3 .3 1" >
            <site site="lower_arm1_pulley_right_back_site" />
            <geom geom="lower_arm2_right_col" sidesite="lower_arm2_right_back_side"/>
            <site site="lower_arm2_attachment_right" />         
        </spatial>

        <spatial name="lower_arm1_tendon_left_front" width="2E-03" rgba=".3 .95 .3 1" >
            <site site="lower_arm1_pulley_left_front_site" />
            <geom geom="lower_arm2_left_col" sidesite="lower_arm2_left_front_side"/>
            <site site="lower_arm2_attachment_left" />         
        </spatial>

        <spatial name="lower_arm1_tendon_left_back" width="2E-03" rgba=".3 .95 .3 1" >
            <site site="lower_arm1_pulley_left_back_site" />
            <geom geom="lower_arm2_left_col" sidesite="lower_arm2_left_back_side"/>
            <site site="lower_arm2_attachment_left" />         
        </spatial>
    </tendon>



    <actuator>
        <motor ctrllimited="true" ctrlrange="-280 280" name="lower_arm1_motor" joint="lower_arm1_joint" />
        
        <!-- <muscle ctrllimited="true" ctrlrange="0 1" name="shoulder0_right_top_motor" tendon="shoulder0_tendon_right_top" />
        <muscle ctrllimited="true" ctrlrange="0 1" name="shoulder0_left_top_motor" tendon="shoulder0_tendon_left_top" />
        <muscle ctrllimited="true" ctrlrange="0 1" name="shoulder0_right_bot_motor" tendon="shoulder0_tendon_right_bot" />
        <muscle ctrllimited="true" ctrlrange="0 1" name="shoulder0_left_bot_motor" tendon="shoulder0_tendon_left_bot" />
        <muscle ctrllimited="true" ctrlrange="0 1" name="shoulder1_back_right_motor" tendon="shoulder1_tendon_back_right" scale="1000"/>
        <muscle ctrllimited="true" ctrlrange="0 1" name="shoulder1_back_left_motor" tendon="shoulder1_tendon_back_left" scale="1000"/>
        <muscle ctrllimited="true" ctrlrange="0 1" name="shoulder1_front_left_motor" tendon="shoulder1_tendon_front_left" scale="1000"/>
        <muscle ctrllimited="true" ctrlrange="0 1" name="shoulder1_front_right_motor" tendon="shoulder1_tendon_front_right" scale="1000"/>
        <muscle ctrllimited="true" ctrlrange="0 1" name="shoulder2_right_top_motor" tendon="shoulder2_tendon_right_top" scale="1000"/>
        <muscle ctrllimited="true" ctrlrange="0 1" name="shoulder2_right_bot_motor" tendon="shoulder2_tendon_right_bot" scale="1000"/>
        <muscle ctrllimited="true" ctrlrange="0 1" name="shoulder2_left_top_motor" tendon="shoulder2_tendon_left_top" scale="1000"/>
        <muscle ctrllimited="true" ctrlrange="0 1" name="shoulder2_left_bot_motor" tendon="shoulder2_tendon_left_bot" scale="1000"/>
        <muscle ctrllimited="true" ctrlrange="0 1" name="upper_arm0_right_bot_motor" tendon="upper_arm0_tendon_right_bot" scale="1000"/>
        <muscle ctrllimited="true" ctrlrange="0 1" name="upper_arm0_right_top_motor" tendon="upper_arm0_tendon_right_top" scale="1000"/>
        <muscle ctrllimited="true" ctrlrange="0 1" name="upper_arm0_left_bot_motor" tendon="upper_arm0_tendon_left_bot" scale="1000"/>
        <muscle ctrllimited="true" ctrlrange="0 1" name="upper_arm0_left_top_motor" tendon="upper_arm0_tendon_left_top" scale="1000"/>
        <muscle ctrllimited="true" ctrlrange="0 1" name="upper_arm1_right_front_motor" tendon="upper_arm1_tendon_right_front" scale="10000"/>
        <muscle ctrllimited="true" ctrlrange="0 1" name="upper_arm1_right_back_motor" tendon="upper_arm1_tendon_right_back" scale="10000"/>
        <muscle ctrllimited="true" ctrlrange="0 1" name="upper_arm1_left_front_motor" tendon="upper_arm1_tendon_left_front" scale="10000"/>
        <muscle ctrllimited="true" ctrlrange="0 1" name="upper_arm1_left_back_motor" tendon="upper_arm1_tendon_left_back" scale="10000"/>
        <muscle ctrllimited="true" ctrlrange="0 1" name="lower_arm1_right_front_motor" tendon="lower_arm1_tendon_right_front" scale="1000"/>
        <muscle ctrllimited="true" ctrlrange="0 1" name="lower_arm1_right_back_motor" tendon="lower_arm1_tendon_right_back" scale="1000"/>
        <muscle ctrllimited="true" ctrlrange="0 1" name="lower_arm1_left_front_motor" tendon="lower_arm1_tendon_left_front" scale="1000"/>
        <muscle ctrllimited="true" ctrlrange="0 1" name="lower_arm1_left_back_motor" tendon="lower_arm1_tendon_left_back" scale="1000"/> -->

        <motor name="shoulder0_right_top_motor" tendon="shoulder0_tendon_right_top" ctrllimited="true" ctrlrange="0.0 280.0"/>
        <motor name="shoulder0_left_top_motor" tendon="shoulder0_tendon_left_top" ctrllimited="true" ctrlrange="0.0 280.0"/>
        <motor name="shoulder0_right_bot_motor" tendon="shoulder0_tendon_right_bot" ctrllimited="true" ctrlrange="0.0 280.0"/>
        <motor name="shoulder0_left_bot_motor" tendon="shoulder0_tendon_left_bot" ctrllimited="true" ctrlrange="0.0 280.0"/>
        <motor name="shoulder1_back_right_motor" tendon="shoulder1_tendon_back_right" ctrllimited="true" ctrlrange="0.0 280.0"/>
        <motor name="shoulder1_back_left_motor" tendon="shoulder1_tendon_back_left" ctrllimited="true" ctrlrange="0.0 280.0"/>
        <motor name="shoulder1_front_left_motor" tendon="shoulder1_tendon_front_left" ctrllimited="true" ctrlrange="0.0 280.0"/>
        <motor name="shoulder1_front_right_motor" tendon="shoulder1_tendon_front_right" ctrllimited="true" ctrlrange="0.0 280.0"/>
        <motor name="shoulder2_right_top_motor" tendon="shoulder2_tendon_right_top" ctrllimited="true" ctrlrange="0.0 280.0"/>
        <motor name="shoulder2_right_bot_motor" tendon="shoulder2_tendon_right_bot" ctrllimited="true" ctrlrange="0.0 280.0"/>
        <motor name="shoulder2_left_top_motor" tendon="shoulder2_tendon_left_top" ctrllimited="true" ctrlrange="0.0 280.0"/>
        <motor name="shoulder2_left_bot_motor" tendon="shoulder2_tendon_left_bot" ctrllimited="true" ctrlrange="0.0 280.0"/>
        <motor name="upper_arm0_right_bot_motor" tendon="upper_arm0_tendon_right_bot" ctrllimited="true" ctrlrange="0.0 280.0"/>
        <motor name="upper_arm0_right_top_motor" tendon="upper_arm0_tendon_right_top" ctrllimited="true" ctrlrange="0.0 280.0"/>
        <motor name="upper_arm0_left_bot_motor" tendon="upper_arm0_tendon_left_bot" ctrllimited="true" ctrlrange="0.0 280.0"/>
        <motor name="upper_arm0_left_top_motor" tendon="upper_arm0_tendon_left_top" ctrllimited="true" ctrlrange="0.0 280.0"/>
        <motor name="upper_arm1_right_front_motor" tendon="upper_arm1_tendon_right_front" ctrllimited="true" ctrlrange="0.0 280.0"/>
        <motor name="upper_arm1_right_back_motor" tendon="upper_arm1_tendon_right_back" ctrllimited="true" ctrlrange="0.0 280.0"/>
        <motor name="upper_arm1_left_front_motor" tendon="upper_arm1_tendon_left_front" ctrllimited="true" ctrlrange="0.0 280.0"/>
        <motor name="upper_arm1_left_back_motor" tendon="upper_arm1_tendon_left_back" ctrllimited="true" ctrlrange="0.0 280.0"/>
        <motor name="lower_arm1_right_front_motor" tendon="lower_arm1_tendon_right_front" ctrllimited="true" ctrlrange="0.0 280.0"/>
        <motor name="lower_arm1_right_back_motor" tendon="lower_arm1_tendon_right_back" ctrllimited="true" ctrlrange="0.0 280.0"/>
        <motor name="lower_arm1_left_front_motor" tendon="lower_arm1_tendon_left_front" ctrllimited="true" ctrlrange="0.0 280.0"/>
        <motor name="lower_arm1_left_back_motor" tendon="lower_arm1_tendon_left_back" ctrllimited="true" ctrlrange="0.0 280.0"/>

    </actuator>
</mujoco>